Workbook

Sheet Paramètres
A1: LES ROIS DU SAHEL
A3: Discipline · Travail · Succès — Gestion des scolarités
A5: Nom de l'établissement | C5: École Les Rois du Sahel
A6: Adresse
A7: Ville / Pays | C7: Niamey, Niger
A8: Téléphone
A9: E-mail
A10: Directeur / Directrice
A11: Année scolaire | C11: 2025-2026
A12: Devise | C12: FCFA
A13: Tableau des scolarités et frais d'inscription (modifiable par classe) :
A14: Classe | B14: Cycle | C14: Scolarité annuelle | D14: Frais d'inscription
A15: Petite section | B15: Maternelle | C15: 150000 | D15: 1000
A16: Grande section | B16: Maternelle | C16: 150000 | D16: 1000
A17: CI | B17: Primaire | C17: 150000 | D17: 1000
A18: CP | B18: Primaire | C18: 150000 | D18: 1000
A19: CE1 | B19: Primaire | C19: 150000 | D19: 1000
A20: CE2 | B20: Primaire | C20: 150000 | D20: 1000
A21: CM1 | B21: Primaire | C21: 150000 | D21: 1000
A22: CM2 | B22: Primaire | C22: 150000 | D22: 1000
A23: 6e | B23: Collège | C23: 150000 | D23: 3000
A24: 5e | B24: Collège | C24: 150000 | D24: 3000
A25: 4e | B25: Collège | C25: 150000 | D25: 3000
A26: 3e | B26: Collège | C26: 150000 | D26: 3000
... A31: Terminale D | B31: Lycée | C31: 150000 | D31: 3000
A33: Mode d'emploi : • Cellules JAUNES = montants à saisir. Ne modifiez pas les colonnes calculées (grises). • N'insérez pas de ligne/colonne dans les tableaux (préserve les formules). • Saisissez les élèves dans la feuille de leur classe (onglets « Classe … », 80 élèves maximum par classe). • « Liste des élèves » est un registre général automatique (lecture seule) : récap, tableau de bord et impayés s'en servent. • Onglet « Reçu de paiement » : tapez un matricule ; 2 reçus (parent + souche) s'impriment sur une feuille A4.

Sheet Classe Petite section
A1: ="INSCRIPTIONS — "&Paramètres!$A$15 -> INSCRIPTIONS — Petite section
A2: ="Année scolaire "&Paramètres!$C$11&" • Effectif : "&COUNTIF($B$4:$B$83,"?*")&" • Cellules jaunes = montants à saisir ; colonnes grises = calcul automatique" -> Année scolaire 2025-2026 • Effectif : 0 • Cellules jaunes = montants à saisir ; colonnes grises = calcul automatique
A3: Matricule | B3: Nom | C3: Prénom(s) | D3: Sexe | E3: Date de naissance | F3: Nom du tuteur | G3: Téléphone | H3: Scolarité due | I3: Tranche 1 | J3: Tranche 2 | K3: Tranche 3 | L3: Total payé | M3: Reste à payer | N3: Inscription due | O3: Inscription payée | P3: Reste inscription | Q3: Statut | R3: Nouveau / Ancien
H4: =IF($B4="","",Paramètres!$C$15) | L4: =IF($B4="","",SUM(I4:K4)) | M4: =IF($B4="","",H4-L4) | N4: =IF($B4="","",IF(R4="Ancien",0,Paramètres!$D$15)) | P4: =IF($B4="","",N4-O4) | Q4: =IF($B4="","",IF(AND(M4<=0,P4<=0),"Soldé","En retard"))
H5: =IF($B5="","",Paramètres!$C$15) | L5: =IF($B5="","",SUM(I5:K5)) | M5: =IF($B5="","",H5-L5) | N5: =IF($B5="","",IF(R5="Ancien",0,Paramètres!$D$15)) | P5: =IF($B5="","",N5-O5) | Q5: =IF($B5="","",IF(AND(M5<=0,P5<=0),"Soldé","En retard"))
H6: =IF($B6="","",Paramètres!$C$15) | L6: =IF($B6="","",SUM(I6:K6)) | M6: =IF($B6="","",H6-L6) | N6: =IF($B6="","",IF(R6="Ancien",0,Paramètres!$D$15)) | P6: =IF($B6="","",N6-O6) | Q6: =IF($B6="","",IF(AND(M6<=0,P6<=0),"Soldé","En retard"))
H7: =IF($B7="","",Paramètres!$C$15) | L7: =IF($B7="","",SUM(I7:K7)) | M7: =IF($B7="","",H7-L7) | N7: =IF($B7="","",IF(R7="Ancien",0,Paramètres!$D$15)) | P7: =IF($B7="","",N7-O7) | Q7: =IF($B7="","",IF(AND(M7<=0,P7<=0),"Soldé","En retard"))
H8: =IF($B8="","",Paramètres!$C$15) | L8: =IF($B8="","",SUM(I8:K8)) | M8: =IF($B8="","",H8-L8) | N8: =IF($B8="","",IF(R8="Ancien",0,Paramètres!$D$15)) | P8: =IF($B8="","",N8-O8) | Q8: =IF($B8="","",IF(AND(M8<=0,P8<=0),"Soldé","En retard"))
H9: =IF($B9="","",Paramètres!$C$15) | L9: =IF($B9="","",SUM(I9:K9)) | M9: =IF($B9="","",H9-L9) | N9: =IF($B9="","",IF(R9="Ancien",0,Paramètres!$D$15)) | P9: =IF($B9="","",N9-O9) | Q9: =IF($B9="","",IF(AND(M9<=0,P9<=0),"Soldé","En retard"))
H10: =IF($B10="","",Paramètres!$C$15) | L10: =IF($B10="","",SUM(I10:K10)) | M10: =IF($B10="","",H10-L10) | N10: =IF($B10="","",IF(R10="Ancien",0,Paramètres!$D$15)) | P10: =IF($B10="","",N10-O10) | Q10: =IF($B10="","",IF(AND(M10<=0,P10<=0),"Soldé","En retard"))
H11: =IF($B11="","",Paramètres!$C$15) | L11: =IF($B11="","",SUM(I11:K11)) | M11: =IF($B11="","",H11-L11) | N11: =IF($B11="","",IF(R11="Ancien",0,Paramètres!$D$15)) | P11: =IF($B11="","",N11-O11) | Q11: =IF($B11="","",IF(AND(M11<=0,P11<=0),"Soldé","En retard"))
H12: =IF($B12="","",Paramètres!$C$15) | L12: =IF($B12="","",SUM(I12:K12)) | M12: =IF($B12="","",H12-L12) | N12: =IF($B12="","",IF(R12="Ancien",0,Paramètres!$D$15)) | P12: =IF($B12="","",N12-O12) | Q12: =IF($B12="","",IF(AND(M12<=0,P12<=0),"Soldé","En retard"))
H13: =IF($B13="","",Paramètres!$C$15) | L13: =IF($B13="","",SUM(I13:K13)) | M13: =IF($B13="","",H13-L13) | N13: =IF($B13="","",IF(R13="Ancien",0,Paramètres!$D$15)) | P13: =IF($B13="","",N13-O13) | Q13: =IF($B13="","",IF(AND(M13<=0,P13<=0),"Soldé","En retard"))
H14: =IF($B14="","",Paramètres!$C$15) | L14: =IF($B14="","",SUM(I14:K14)) | M14: =IF($B14="","",H14-L14) | N14: =IF($B14="","",IF(R14="Ancien",0,Paramètres!$D$15)) | P14: =IF($B14="","",N14-O14) | Q14: =IF($B14="","",IF(AND(M14<=0,P14<=0),"Soldé","En retard"))
H15: =IF($B15="","",Paramètres!$C$15) | L15: =IF($B15="","",SUM(I15:K15)) | M15: =IF($B15="","",H15-L15) | N15: =IF($B15="","",IF(R15="Ancien",0,Paramètres!$D$15)) | P15: =IF($B15="","",N15-O15) | Q15: =IF($B15="","",IF(AND(M15<=0,P15<=0),"Soldé","En retard"))
... H83: =IF($B83="","",Paramètres!$C$15) | L83: =IF($B83="","",SUM(I83:K83)) | M83: =IF($B83="","",H83-L83) | N83: =IF($B83="","",IF(R83="Ancien",0,Paramètres!$D$15)) | P83: =IF($B83="","",N83-O83) | Q83: =IF($B83="","",IF(AND(M83<=0,P83<=0),"Soldé","En retard"))

Sheet Classe Grande section
A1: ="INSCRIPTIONS — "&Paramètres!$A$16 -> INSCRIPTIONS — Grande section
A2: ="Année scolaire "&Paramètres!$C$11&" • Effectif : "&COUNTIF($B$4:$B$83,"?*")&" • Cellules jaunes = montants à saisir ; colonnes grises = calcul automatique" -> Année scolaire 2025-2026 • Effectif : 0 • Cellules jaunes = montants à saisir ; colonnes grises = calcul automatique
A3: Matricule | B3: Nom | C3: Prénom(s) | D3: Sexe | E3: Date de naissance | F3: Nom du tuteur | G3: Téléphone | H3: Scolarité due | I3: Tranche 1 | J3: Tranche 2 | K3: Tranche 3 | L3: Total payé | M3: Reste à payer | N3: Inscription due | O3: Inscription payée | P3: Reste inscription | Q3: Statut | R3: Nouveau / Ancien
H4: =IF($B4="","",Paramètres!$C$16) | L4: =IF($B4="","",SUM(I4:K4)) | M4: =IF($B4="","",H4-L4) | N4: =IF($B4="","",IF(R4="Ancien",0,Paramètres!$D$16)) | P4: =IF($B4="","",N4-O4) | Q4: =IF($B4="","",IF(AND(M4<=0,P4<=0),"Soldé","En retard"))
H5: =IF($B5="","",Paramètres!$C$16) | L5: =IF($B5="","",SUM(I5:K5)) | M5: =IF($B5="","",H5-L5) | N5: =IF($B5="","",IF(R5="Ancien",0,Paramètres!$D$16)) | P5: =IF($B5="","",N5-O5) | Q5: =IF($B5="","",IF(AND(M5<=0,P5<=0),"Soldé","En retard"))
H6: =IF($B6="","",Paramètres!$C$16) | L6: =IF($B6="","",SUM(I6:K6)) | M6: =IF($B6="","",H6-L6) | N6: =IF($B6="","",IF(R6="Ancien",0,Paramètres!$D$16)) | P6: =IF($B6="","",N6-O6) | Q6: =IF($B6="","",IF(AND(M6<=0,P6<=0),"Soldé","En retard"))
H7: =IF($B7="","",Paramètres!$C$16) | L7: =IF($B7="","",SUM(I7:K7)) | M7: =IF($B7="","",H7-L7) | N7: =IF($B7="","",IF(R7="Ancien",0,Paramètres!$D$16)) | P7: =IF($B7="","",N7-O7) | Q7: =IF($B7="","",IF(AND(M7<=0,P7<=0),"Soldé","En retard"))
H8: =IF($B8="","",Paramètres!$C$16) | L8: =IF($B8="","",SUM(I8:K8)) | M8: =IF($B8="","",H8-L8) | N8: =IF($B8="","",IF(R8="Ancien",0,Paramètres!$D$16)) | P8: =IF($B8="","",N8-O8) | Q8: =IF($B8="","",IF(AND(M8<=0,P8<=0),"Soldé","En retard"))
H9: =IF($B9="","",Paramètres!$C$16) | L9: =IF($B9="","",SUM(I9:K9)) | M9: =IF($B9="","",H9-L9) | N9: =IF($B9="","",IF(R9="Ancien",0,Paramètres!$D$16)) | P9: =IF($B9="","",N9-O9) | Q9: =IF($B9="","",IF(AND(M9<=0,P9<=0),"Soldé","En retard"))
H10: =IF($B10="","",Paramètres!$C$16) | L10: =IF($B10="","",SUM(I10:K10)) | M10: =IF($B10="","",H10-L10) | N10: =IF($B10="","",IF(R10="Ancien",0,Paramètres!$D$16)) | P10: =IF($B10="","",N10-O10) | Q10: =IF($B10="","",IF(AND(M10<=0,P10<=0),"Soldé","En retard"))
H11: =IF($B11="","",Paramètres!$C$16) | L11: =IF($B11="","",SUM(I11:K11)) | M11: =IF($B11="","",H11-L11) | N11: =IF($B11="","",IF(R11="Ancien",0,Paramètres!$D$16)) | P11: =IF($B11="","",N11-O11) | Q11: =IF($B11="","",IF(AND(M11<=0,P11<=0),"Soldé","En retard"))
H12: =IF($B12="","",Paramètres!$C$16) | L12: =IF($B12="","",SUM(I12:K12)) | M12: =IF($B12="","",H12-L12) | N12: =IF($B12="","",IF(R12="Ancien",0,Paramètres!$D$16)) | P12: =IF($B12="","",N12-O12) | Q12: =IF($B12="","",IF(AND(M12<=0,P12<=0),"Soldé","En retard"))
H13: =IF($B13="","",Paramètres!$C$16) | L13: =IF($B13="","",SUM(I13:K13)) | M13: =IF($B13="","",H13-L13) | N13: =IF($B13="","",IF(R13="Ancien",0,Paramètres!$D$16)) | P13: =IF($B13="","",N13-O13) | Q13: =IF($B13="","",IF(AND(M13<=0,P13<=0),"Soldé","En retard"))
H14: =IF($B14="","",Paramètres!$C$16) | L14: =IF($B14="","",SUM(I14:K14)) | M14: =IF($B14="","",H14-L14) | N14: =IF($B14="","",IF(R14="Ancien",0,Paramètres!$D$16)) | P14: =IF($B14="","",N14-O14) | Q14: =IF($B14="","",IF(AND(M14<=0,P14<=0),"Soldé","En retard"))
H15: =IF($B15="","",Paramètres!$C$16) | L15: =IF($B15="","",SUM(I15:K15)) | M15: =IF($B15="","",H15-L15) | N15: =IF($B15="","",IF(R15="Ancien",0,Paramètres!$D$16)) | P15: =IF($B15="","",N15-O15) | Q15: =IF($B15="","",IF(AND(M15<=0,P15<=0),"Soldé","En retard"))
... H83: =IF($B83="","",Paramètres!$C$16) | L83: =IF($B83="","",SUM(I83:K83)) | M83: =IF($B83="","",H83-L83) | N83: =IF($B83="","",IF(R83="Ancien",0,Paramètres!$D$16)) | P83: =IF($B83="","",N83-O83) | Q83: =IF($B83="","",IF(AND(M83<=0,P83<=0),"Soldé","En retard"))

Sheet Classe CI
A1: ="INSCRIPTIONS — "&Paramètres!$A$17 -> INSCRIPTIONS — CI
A2: ="Année scolaire "&Paramètres!$C$11&" • Effectif : "&COUNTIF($B$4:$B$83,"?*")&" • Cellules jaunes = montants à saisir ; colonnes grises = calcul automatique" -> Année scolaire 2025-2026 • Effectif : 0 • Cellules jaunes = montants à saisir ; colonnes grises = calcul automatique
A3: Matricule | B3: Nom | C3: Prénom(s) | D3: Sexe | E3: Date de naissance | F3: Nom du tuteur | G3: Téléphone | H3: Scolarité due | I3: Tranche 1 | J3: Tranche 2 | K3: Tranche 3 | L3: Total payé | M3: Reste à payer | N3: Inscription due | O3: Inscription payée | P3: Reste inscription | Q3: Statut | R3: Nouveau / Ancien
H4: =IF($B4="","",Paramètres!$C$17) | L4: =IF($B4="","",SUM(I4:K4)) | M4: =IF($B4="","",H4-L4) | N4: =IF($B4="","",IF(R4="Ancien",0,Paramètres!$D$17)) | P4: =IF($B4="","",N4-O4) | Q4: =IF($B4="","",IF(AND(M4<=0,P4<=0),"Soldé","En retard"))
H5: =IF($B5="","",Paramètres!$C$17) | L5: =IF($B5="","",SUM(I5:K5)) | M5: =IF($B5="","",H5-L5) | N5: =IF($B5="","",IF(R5="Ancien",0,Paramètres!$D$17)) | P5: =IF($B5="","",N5-O5) | Q5: =IF($B5="","",IF(AND(M5<=0,P5<=0),"Soldé","En retard"))
H6: =IF($B6="","",Paramètres!$C$17) | L6: =IF($B6="","",SUM(I6:K6)) | M6: =IF($B6="","",H6-L6) | N6: =IF($B6="","",IF(R6="Ancien",0,Paramètres!$D$17)) | P6: =IF($B6="","",N6-O6) | Q6: =IF($B6="","",IF(AND(M6<=0,P6<=0),"Soldé","En retard"))
H7: =IF($B7="","",Paramètres!$C$17) | L7: =IF($B7="","",SUM(I7:K7)) | M7: =IF($B7="","",H7-L7) | N7: =IF($B7="","",IF(R7="Ancien",0,Paramètres!$D$17)) | P7: =IF($B7="","",N7-O7) | Q7: =IF($B7="","",IF(AND(M7<=0,P7<=0),"Soldé","En retard"))
H8: =IF($B8="","",Paramètres!$C$17) | L8: =IF($B8="","",SUM(I8:K8)) | M8: =IF($B8="","",H8-L8) | N8: =IF($B8="","",IF(R8="Ancien",0,Paramètres!$D$17)) | P8: =IF($B8="","",N8-O8) | Q8: =IF($B8="","",IF(AND(M8<=0,P8<=0),"Soldé","En retard"))
H9: =IF($B9="","",Paramètres!$C$17) | L9: =IF($B9="","",SUM(I9:K9)) | M9: =IF($B9="","",H9-L9) | N9: =IF($B9="","",IF(R9="Ancien",0,Paramètres!$D$17)) | P9: =IF($B9="","",N9-O9) | Q9: =IF($B9="","",IF(AND(M9<=0,P9<=0),"Soldé","En retard"))
H10: =IF($B10="","",Paramètres!$C$17) | L10: =IF($B10="","",SUM(I10:K10)) | M10: =IF($B10="","",H10-L10) | N10: =IF($B10="","",IF(R10="Ancien",0,Paramètres!$D$17)) | P10: =IF($B10="","",N10-O10) | Q10: =IF($B10="","",IF(AND(M10<=0,P10<=0),"Soldé","En retard"))
H11: =IF($B11="","",Paramètres!$C$17) | L11: =IF($B11="","",SUM(I11:K11)) | M11: =IF($B11="","",H11-L11) | N11: =IF($B11="","",IF(R11="Ancien",0,Paramètres!$D$17)) | P11: =IF($B11="","",N11-O11) | Q11: =IF($B11="","",IF(AND(M11<=0,P11<=0),"Soldé","En retard"))
H12: =IF($B12="","",Paramètres!$C$17) | L12: =IF($B12="","",SUM(I12:K12)) | M12: =IF($B12="","",H12-L12) | N12: =IF($B12="","",IF(R12="Ancien",0,Paramètres!$D$17)) | P12: =IF($B12="","",N12-O12) | Q12: =IF($B12="","",IF(AND(M12<=0,P12<=0),"Soldé","En retard"))
H13: =IF($B13="","",Paramètres!$C$17) | L13: =IF($B13="","",SUM(I13:K13)) | M13: =IF($B13="","",H13-L13) | N13: =IF($B13="","",IF(R13="Ancien",0,Paramètres!$D$17)) | P13: =IF($B13="","",N13-O13) | Q13: =IF($B13="","",IF(AND(M13<=0,P13<=0),"Soldé","En retard"))
H14: =IF($B14="","",Paramètres!$C$17) | L14: =IF($B14="","",SUM(I14:K14)) | M14: =IF($B14="","",H14-L14) | N14: =IF($B14="","",IF(R14="Ancien",0,Paramètres!$D$17)) | P14: =IF($B14="","",N14-O14) | Q14: =IF($B14="","",IF(AND(M14<=0,P14<=0),"Soldé","En retard"))
H15: =IF($B15="","",Paramètres!$C$17) | L15: =IF($B15="","",SUM(I15:K15)) | M15: =IF($B15="","",H15-L15) | N15: =IF($B15="","",IF(R15="Ancien",0,Paramètres!$D$17)) | P15: =IF($B15="","",N15-O15) | Q15: =IF($B15="","",IF(AND(M15<=0,P15<=0),"Soldé","En retard"))
... H83: =IF($B83="","",Paramètres!$C$17) | L83: =IF($B83="","",SUM(I83:K83)) | M83: =IF($B83="","",H83-L83) | N83: =IF($B83="","",IF(R83="Ancien",0,Paramètres!$D$17)) | P83: =IF($B83="","",N83-O83) | Q83: =IF($B83="","",IF(AND(M83<=0,P83<=0),"Soldé","En retard"))

Sheet Classe CP
A1: ="INSCRIPTIONS — "&Paramètres!$A$18 -> INSCRIPTIONS — CP
A2: ="Année scolaire "&Paramètres!$C$11&" • Effectif : "&COUNTIF($B$4:$B$83,"?*")&" • Cellules jaunes = montants à saisir ; colonnes grises = calcul automatique" -> Année scolaire 2025-2026 • Effectif : 0 • Cellules jaunes = montants à saisir ; colonnes grises = calcul automatique
A3: Matricule | B3: Nom | C3: Prénom(s) | D3: Sexe | E3: Date de naissance | F3: Nom du tuteur | G3: Téléphone | H3: Scolarité due | I3: Tranche 1 | J3: Tranche 2 | K3: Tranche 3 | L3: Total payé | M3: Reste à payer | N3: Inscription due | O3: Inscription payée | P3: Reste inscription | Q3: Statut | R3: Nouveau / Ancien
H4: =IF($B4="","",Paramètres!$C$18) | L4: =IF($B4="","",SUM(I4:K4)) | M4: =IF($B4="","",H4-L4) | N4: =IF($B4="","",IF(R4="Ancien",0,Paramètres!$D$18)) | P4: =IF($B4="","",N4-O4) | Q4: =IF($B4="","",IF(AND(M4<=0,P4<=0),"Soldé","En retard"))
H5: =IF($B5="","",Paramètres!$C$18) | L5: =IF($B5="","",SUM(I5:K5)) | M5: =IF($B5="","",H5-L5) | N5: =IF($B5="","",IF(R5="Ancien",0,Paramètres!$D$18)) | P5: =IF($B5="","",N5-O5) | Q5: =IF($B5="","",IF(AND(M5<=0,P5<=0),"Soldé","En retard"))
H6: =IF($B6="","",Paramètres!$C$18) | L6: =IF($B6="","",SUM(I6:K6)) | M6: =IF($B6="","",H6-L6) | N6: =IF($B6="","",IF(R6="Ancien",0,Paramètres!$D$18)) | P6: =IF($B6="","",N6-O6) | Q6: =IF($B6="","",IF(AND(M6<=0,P6<=0),"Soldé","En retard"))
H7: =IF($B7="","",Paramètres!$C$18) | L7: =IF($B7="","",SUM(I7:K7)) | M7: =IF($B7="","",H7-L7) | N7: =IF($B7="","",IF(R7="Ancien",0,Paramètres!$D$18)) | P7: =IF($B7="","",N7-O7) | Q7: =IF($B7="","",IF(AND(M7<=0,P7<=0),"Soldé","En retard"))
H8: =IF($B8="","",Paramètres!$C$18) | L8: =IF($B8="","",SUM(I8:K8)) | M8: =IF($B8="","",H8-L8) | N8: =IF($B8="","",IF(R8="Ancien",0,Paramètres!$D$18)) | P8: =IF($B8="","",N8-O8) | Q8: =IF($B8="","",IF(AND(M8<=0,P8<=0),"Soldé","En retard"))
H9: =IF($B9="","",Paramètres!$C$18) | L9: =IF($B9="","",SUM(I9:K9)) | M9: =IF($B9="","",H9-L9) | N9: =IF($B9="","",IF(R9="Ancien",0,Paramètres!$D$18)) | P9: =IF($B9="","",N9-O9) | Q9: =IF($B9="","",IF(AND(M9<=0,P9<=0),"Soldé","En retard"))
H10: =IF($B10="","",Paramètres!$C$18) | L10: =IF($B10="","",SUM(I10:K10)) | M10: =IF($B10="","",H10-L10) | N10: =IF($B10="","",IF(R10="Ancien",0,Paramètres!$D$18)) | P10: =IF($B10="","",N10-O10) | Q10: =IF($B10="","",IF(AND(M10<=0,P10<=0),"Soldé","En retard"))
H11: =IF($B11="","",Paramètres!$C$18) | L11: =IF($B11="","",SUM(I11:K11)) | M11: =IF($B11="","",H11-L11) | N11: =IF($B11="","",IF(R11="Ancien",0,Paramètres!$D$18)) | P11: =IF($B11="","",N11-O11) | Q11: =IF($B11="","",IF(AND(M11<=0,P11<=0),"Soldé","En retard"))
H12: =IF($B12="","",Paramètres!$C$18) | L12: =IF($B12="","",SUM(I12:K12)) | M12: =IF($B12="","",H12-L12) | N12: =IF($B12="","",IF(R12="Ancien",0,Paramètres!$D$18)) | P12: =IF($B12="","",N12-O12) | Q12: =IF($B12="","",IF(AND(M12<=0,P12<=0),"Soldé","En retard"))
H13: =IF($B13="","",Paramètres!$C$18) | L13: =IF($B13="","",SUM(I13:K13)) | M13: =IF($B13="","",H13-L13) | N13: =IF($B13="","",IF(R13="Ancien",0,Paramètres!$D$18)) | P13: =IF($B13="","",N13-O13) | Q13: =IF($B13="","",IF(AND(M13<=0,P13<=0),"Soldé","En retard"))
H14: =IF($B14="","",Paramètres!$C$18) | L14: =IF($B14="","",SUM(I14:K14)) | M14: =IF($B14="","",H14-L14) | N14: =IF($B14="","",IF(R14="Ancien",0,Paramètres!$D$18)) | P14: =IF($B14="","",N14-O14) | Q14: =IF($B14="","",IF(AND(M14<=0,P14<=0),"Soldé","En retard"))
H15: =IF($B15="","",Paramètres!$C$18) | L15: =IF($B15="","",SUM(I15:K15)) | M15: =IF($B15="","",H15-L15) | N15: =IF($B15="","",IF(R15="Ancien",0,Paramètres!$D$18)) | P15: =IF($B15="","",N15-O15) | Q15: =IF($B15="","",IF(AND(M15<=0,P15<=0),"Soldé","En retard"))
... H83: =IF($B83="","",Paramètres!$C$18) | L83: =IF($B83="","",SUM(I83:K83)) | M83: =IF($B83="","",H83-L83) | N83: =IF($B83="","",IF(R83="Ancien",0,Paramètres!$D$18)) | P83: =IF($B83="","",N83-O83) | Q83: =IF($B83="","",IF(AND(M83<=0,P83<=0),"Soldé","En retard"))

Sheet Classe CE1
A1: ="INSCRIPTIONS — "&Paramètres!$A$19 -> INSCRIPTIONS — CE1
A2: ="Année scolaire "&Paramètres!$C$11&" • Effectif : "&COUNTIF($B$4:$B$83,"?*")&" • Cellules jaunes = montants à saisir ; colonnes grises = calcul automatique" -> Année scolaire 2025-2026 • Effectif : 0 • Cellules jaunes = montants à saisir ; colonnes grises = calcul automatique
A3: Matricule | B3: Nom | C3: Prénom(s) | D3: Sexe | E3: Date de naissance | F3: Nom du tuteur | G3: Téléphone | H3: Scolarité due | I3: Tranche 1 | J3: Tranche 2 | K3: Tranche 3 | L3: Total payé | M3: Reste à payer | N3: Inscription due | O3: Inscription payée | P3: Reste inscription | Q3: Statut | R3: Nouveau / Ancien
H4: =IF($B4="","",Paramètres!$C$19) | L4: =IF($B4="","",SUM(I4:K4)) | M4: =IF($B4="","",H4-L4) | N4: =IF($B4="","",IF(R4="Ancien",0,Paramètres!$D$19)) | P4: =IF($B4="","",N4-O4) | Q4: =IF($B4="","",IF(AND(M4<=0,P4<=0),"Soldé","En retard"))
H5: =IF($B5="","",Paramètres!$C$19) | L5: =IF($B5="","",SUM(I5:K5)) | M5: =IF($B5="","",H5-L5) | N5: =IF($B5="","",IF(R5="Ancien",0,Paramètres!$D$19)) | P5: =IF($B5="","",N5-O5) | Q5: =IF($B5="","",IF(AND(M5<=0,P5<=0),"Soldé","En retard"))
H6: =IF($B6="","",Paramètres!$C$19) | L6: =IF($B6="","",SUM(I6:K6)) | M6: =IF($B6="","",H6-L6) | N6: =IF($B6="","",IF(R6="Ancien",0,Paramètres!$D$19)) | P6: =IF($B6="","",N6-O6) | Q6: =IF($B6="","",IF(AND(M6<=0,P6<=0),"Soldé","En retard"))
H7: =IF($B7="","",Paramètres!$C$19) | L7: =IF($B7="","",SUM(I7:K7)) | M7: =IF($B7="","",H7-L7) | N7: =IF($B7="","",IF(R7="Ancien",0,Paramètres!$D$19)) | P7: =IF($B7="","",N7-O7) | Q7: =IF($B7="","",IF(AND(M7<=0,P7<=0),"Soldé","En retard"))
H8: =IF($B8="","",Paramètres!$C$19) | L8: =IF($B8="","",SUM(I8:K8)) | M8: =IF($B8="","",H8-L8) | N8: =IF($B8="","",IF(R8="Ancien",0,Paramètres!$D$19)) | P8: =IF($B8="","",N8-O8) | Q8: =IF($B8="","",IF(AND(M8<=0,P8<=0),"Soldé","En retard"))
H9: =IF($B9="","",Paramètres!$C$19) | L9: =IF($B9="","",SUM(I9:K9)) | M9: =IF($B9="","",H9-L9) | N9: =IF($B9="","",IF(R9="Ancien",0,Paramètres!$D$19)) | P9: =IF($B9="","",N9-O9) | Q9: =IF($B9="","",IF(AND(M9<=0,P9<=0),"Soldé","En retard"))
H10: =IF($B10="","",Paramètres!$C$19) | L10: =IF($B10="","",SUM(I10:K10)) | M10: =IF($B10="","",H10-L10) | N10: =IF($B10="","",IF(R10="Ancien",0,Paramètres!$D$19)) | P10: =IF($B10="","",N10-O10) | Q10: =IF($B10="","",IF(AND(M10<=0,P10<=0),"Soldé","En retard"))
H11: =IF($B11="","",Paramètres!$C$19) | L11: =IF($B11="","",SUM(I11:K11)) | M11: =IF($B11="","",H11-L11) | N11: =IF($B11="","",IF(R11="Ancien",0,Paramètres!$D$19)) | P11: =IF($B11="","",N11-O11) | Q11: =IF($B11="","",IF(AND(M11<=0,P11<=0),"Soldé","En retard"))
H12: =IF($B12="","",Paramètres!$C$19) | L12: =IF($B12="","",SUM(I12:K12)) | M12: =IF($B12="","",H12-L12) | N12: =IF($B12="","",IF(R12="Ancien",0,Paramètres!$D$19)) | P12: =IF($B12="","",N12-O12) | Q12: =IF($B12="","",IF(AND(M12<=0,P12<=0),"Soldé","En retard"))
H13: =IF($B13="","",Paramètres!$C$19) | L13: =IF($B13="","",SUM(I13:K13)) | M13: =IF($B13="","",H13-L13) | N13: =IF($B13="","",IF(R13="Ancien",0,Paramètres!$D$19)) | P13: =IF($B13="","",N13-O13) | Q13: =IF($B13="","",IF(AND(M13<=0,P13<=0),"Soldé","En retard"))
H14: =IF($B14="","",Paramètres!$C$19) | L14: =IF($B14="","",SUM(I14:K14)) | M14: =IF($B14="","",H14-L14) | N14: =IF($B14="","",IF(R14="Ancien",0,Paramètres!$D$19)) | P14: =IF($B14="","",N14-O14) | Q14: =IF($B14="","",IF(AND(M14<=0,P14<=0),"Soldé","En retard"))
H15: =IF($B15="","",Paramètres!$C$19) | L15: =IF($B15="","",SUM(I15:K15)) | M15: =IF($B15="","",H15-L15) | N15: =IF($B15="","",IF(R15="Ancien",0,Paramètres!$D$19)) | P15: =IF($B15="","",N15-O15) | Q15: =IF($B15="","",IF(AND(M15<=0,P15<=0),"Soldé","En retard"))
... H83: =IF($B83="","",Paramètres!$C$19) | L83: =IF($B83="","",SUM(I83:K83)) | M83: =IF($B83="","",H83-L83) | N83: =IF($B83="","",IF(R83="Ancien",0,Paramètres!$D$19)) | P83: =IF($B83="","",N83-O83) | Q83: =IF($B83="","",IF(AND(M83<=0,P83<=0),"Soldé","En retard"))

Sheet Classe CE2
A1: ="INSCRIPTIONS — "&Paramètres!$A$20 -> INSCRIPTIONS — CE2
A2: ="Année scolaire "&Paramètres!$C$11&" • Effectif : "&COUNTIF($B$4:$B$83,"?*")&" • Cellules jaunes = montants à saisir ; colonnes grises = calcul automatique" -> Année scolaire 2025-2026 • Effectif : 0 • Cellules jaunes = montants à saisir ; colonnes grises = calcul automatique
A3: Matricule | B3: Nom | C3: Prénom(s) | D3: Sexe | E3: Date de naissance | F3: Nom du tuteur | G3: Téléphone | H3: Scolarité due | I3: Tranche 1 | J3: Tranche 2 | K3: Tranche 3 | L3: Total payé | M3: Reste à payer | N3: Inscription due | O3: Inscription payée | P3: Reste inscription | Q3: Statut | R3: Nouveau / Ancien
H4: =IF($B4="","",Paramètres!$C$20) | L4: =IF($B4="","",SUM(I4:K4)) | M4: =IF($B4="","",H4-L4) | N4: =IF($B4="","",IF(R4="Ancien",0,Paramètres!$D$20)) | P4: =IF($B4="","",N4-O4) | Q4: =IF($B4="","",IF(AND(M4<=0,P4<=0),"Soldé","En retard"))
H5: =IF($B5="","",Paramètres!$C$20) | L5: =IF($B5="","",SUM(I5:K5)) | M5: =IF($B5="","",H5-L5) | N5: =IF($B5="","",IF(R5="Ancien",0,Paramètres!$D$20)) | P5: =IF($B5="","",N5-O5) | Q5: =IF($B5="","",IF(AND(M5<=0,P5<=0),"Soldé","En retard"))
H6: =IF($B6="","",Paramètres!$C$20) | L6: =IF($B6="","",SUM(I6:K6)) | M6: =IF($B6="","",H6-L6) | N6: =IF($B6="","",IF(R6="Ancien",0,Paramètres!$D$20)) | P6: =IF($B6="","",N6-O6) | Q6: =IF($B6="","",IF(AND(M6<=0,P6<=0),"Soldé","En retard"))
H7: =IF($B7="","",Paramètres!$C$20) | L7: =IF($B7="","",SUM(I7:K7)) | M7: =IF($B7="","",H7-L7) | N7: =IF($B7="","",IF(R7="Ancien",0,Paramètres!$D$20)) | P7: =IF($B7="","",N7-O7) | Q7: =IF($B7="","",IF(AND(M7<=0,P7<=0),"Soldé","En retard"))
H8: =IF($B8="","",Paramètres!$C$20) | L8: =IF($B8="","",SUM(I8:K8)) | M8: =IF($B8="","",H8-L8) | N8: =IF($B8="","",IF(R8="Ancien",0,Paramètres!$D$20)) | P8: =IF($B8="","",N8-O8) | Q8: =IF($B8="","",IF(AND(M8<=0,P8<=0),"Soldé","En retard"))
H9: =IF($B9="","",Paramètres!$C$20) | L9: =IF($B9="","",SUM(I9:K9)) | M9: =IF($B9="","",H9-L9) | N9: =IF($B9="","",IF(R9="Ancien",0,Paramètres!$D$20)) | P9: =IF($B9="","",N9-O9) | Q9: =IF($B9="","",IF(AND(M9<=0,P9<=0),"Soldé","En retard"))
H10: =IF($B10="","",Paramètres!$C$20) | L10: =IF($B10="","",SUM(I10:K10)) | M10: =IF($B10="","",H10-L10) | N10: =IF($B10="","",IF(R10="Ancien",0,Paramètres!$D$20)) | P10: =IF($B10="","",N10-O10) | Q10: =IF($B10="","",IF(AND(M10<=0,P10<=0),"Soldé","En retard"))
H11: =IF($B11="","",Paramètres!$C$20) | L11: =IF($B11="","",SUM(I11:K11)) | M11: =IF($B11="","",H11-L11) | N11: =IF($B11="","",IF(R11="Ancien",0,Paramètres!$D$20)) | P11: =IF($B11="","",N11-O11) | Q11: =IF($B11="","",IF(AND(M11<=0,P11<=0),"Soldé","En retard"))
H12: =IF($B12="","",Paramètres!$C$20) | L12: =IF($B12="","",SUM(I12:K12)) | M12: =IF($B12="","",H12-L12) | N12: =IF($B12="","",IF(R12="Ancien",0,Paramètres!$D$20)) | P12: =IF($B12="","",N12-O12) | Q12: =IF($B12="","",IF(AND(M12<=0,P12<=0),"Soldé","En retard"))
H13: =IF($B13="","",Paramètres!$C$20) | L13: =IF($B13="","",SUM(I13:K13)) | M13: =IF($B13="","",H13-L13) | N13: =IF($B13="","",IF(R13="Ancien",0,Paramètres!$D$20)) | P13: =IF($B13="","",N13-O13) | Q13: =IF($B13="","",IF(AND(M13<=0,P13<=0),"Soldé","En retard"))
H14: =IF($B14="","",Paramètres!$C$20) | L14: =IF($B14="","",SUM(I14:K14)) | M14: =IF($B14="","",H14-L14) | N14: =IF($B14="","",IF(R14="Ancien",0,Paramètres!$D$20)) | P14: =IF($B14="","",N14-O14) | Q14: =IF($B14="","",IF(AND(M14<=0,P14<=0),"Soldé","En retard"))
H15: =IF($B15="","",Paramètres!$C$20) | L15: =IF($B15="","",SUM(I15:K15)) | M15: =IF($B15="","",H15-L15) | N15: =IF($B15="","",IF(R15="Ancien",0,Paramètres!$D$20)) | P15: =IF($B15="","",N15-O15) | Q15: =IF($B15="","",IF(AND(M15<=0,P15<=0),"Soldé","En retard"))
... H83: =IF($B83="","",Paramètres!$C$20) | L83: =IF($B83="","",SUM(I83:K83)) | M83: =IF($B83="","",H83-L83) | N83: =IF($B83="","",IF(R83="Ancien",0,Paramètres!$D$20)) | P83: =IF($B83="","",N83-O83) | Q83: =IF($B83="","",IF(AND(M83<=0,P83<=0),"Soldé","En retard"))

Sheet Classe CM1
A1: ="INSCRIPTIONS — "&Paramètres!$A$21 -> INSCRIPTIONS — CM1
A2: ="Année scolaire "&Paramètres!$C$11&" • Effectif : "&COUNTIF($B$4:$B$83,"?*")&" • Cellules jaunes = montants à saisir ; colonnes grises = calcul automatique" -> Année scolaire 2025-2026 • Effectif : 0 • Cellules jaunes = montants à saisir ; colonnes grises = calcul automatique
A3: Matricule | B3: Nom | C3: Prénom(s) | D3: Sexe | E3: Date de naissance | F3: Nom du tuteur | G3: Téléphone | H3: Scolarité due | I3: Tranche 1 | J3: Tranche 2 | K3: Tranche 3 | L3: Total payé | M3: Reste à payer | N3: Inscription due | O3: Inscription payée | P3: Reste inscription | Q3: Statut | R3: Nouveau / Ancien
H4: =IF($B4="","",Paramètres!$C$21) | L4: =IF($B4="","",SUM(I4:K4)) | M4: =IF($B4="","",H4-L4) | N4: =IF($B4="","",IF(R4="Ancien",0,Paramètres!$D$21)) | P4: =IF($B4="","",N4-O4) | Q4: =IF($B4="","",IF(AND(M4<=0,P4<=0),"Soldé","En retard"))
H5: =IF($B5="","",Paramètres!$C$21) | L5: =IF($B5="","",SUM(I5:K5)) | M5: =IF($B5="","",H5-L5) | N5: =IF($B5="","",IF(R5="Ancien",0,Paramètres!$D$21)) | P5: =IF($B5="","",N5-O5) | Q5: =IF($B5="","",IF(AND(M5<=0,P5<=0),"Soldé","En retard"))
H6: =IF($B6="","",Paramètres!$C$21) | L6: =IF($B6="","",SUM(I6:K6)) | M6: =IF($B6="","",H6-L6) | N6: =IF($B6="","",IF(R6="Ancien",0,Paramètres!$D$21)) | P6: =IF($B6="","",N6-O6) | Q6: =IF($B6="","",IF(AND(M6<=0,P6<=0),"Soldé","En retard"))
H7: =IF($B7="","",Paramètres!$C$21) | L7: =IF($B7="","",SUM(I7:K7)) | M7: =IF($B7="","",H7-L7) | N7: =IF($B7="","",IF(R7="Ancien",0,Paramètres!$D$21)) | P7: =IF($B7="","",N7-O7) | Q7: =IF($B7="","",IF(AND(M7<=0,P7<=0),"Soldé","En retard"))
H8: =IF($B8="","",Paramètres!$C$21) | L8: =IF($B8="","",SUM(I8:K8)) | M8: =IF($B8="","",H8-L8) | N8: =IF($B8="","",IF(R8="Ancien",0,Paramètres!$D$21)) | P8: =IF($B8="","",N8-O8) | Q8: =IF($B8="","",IF(AND(M8<=0,P8<=0),"Soldé","En retard"))
H9: =IF($B9="","",Paramètres!$C$21) | L9: =IF($B9="","",SUM(I9:K9)) | M9: =IF($B9="","",H9-L9) | N9: =IF($B9="","",IF(R9="Ancien",0,Paramètres!$D$21)) | P9: =IF($B9="","",N9-O9) | Q9: =IF($B9="","",IF(AND(M9<=0,P9<=0),"Soldé","En retard"))
H10: =IF($B10="","",Paramètres!$C$21) | L10: =IF($B10="","",SUM(I10:K10)) | M10: =IF($B10="","",H10-L10) | N10: =IF($B10="","",IF(R10="Ancien",0,Paramètres!$D$21)) | P10: =IF($B10="","",N10-O10) | Q10: =IF($B10="","",IF(AND(M10<=0,P10<=0),"Soldé","En retard"))
H11: =IF($B11="","",Paramètres!$C$21) | L11: =IF($B11="","",SUM(I11:K11)) | M11: =IF($B11="","",H11-L11) | N11: =IF($B11="","",IF(R11="Ancien",0,Paramètres!$D$21)) | P11: =IF($B11="","",N11-O11) | Q11: =IF($B11="","",IF(AND(M11<=0,P11<=0),"Soldé","En retard"))
H12: =IF($B12="","",Paramètres!$C$21) | L12: =IF($B12="","",SUM(I12:K12)) | M12: =IF($B12="","",H12-L12) | N12: =IF($B12="","",IF(R12="Ancien",0,Paramètres!$D$21)) | P12: =IF($B12="","",N12-O12) | Q12: =IF($B12="","",IF(AND(M12<=0,P12<=0),"Soldé","En retard"))
H13: =IF($B13="","",Paramètres!$C$21) | L13: =IF($B13="","",SUM(I13:K13)) | M13: =IF($B13="","",H13-L13) | N13: =IF($B13="","",IF(R13="Ancien",0,Paramètres!$D$21)) | P13: =IF($B13="","",N13-O13) | Q13: =IF($B13="","",IF(AND(M13<=0,P13<=0),"Soldé","En retard"))
H14: =IF($B14="","",Paramètres!$C$21) | L14: =IF($B14="","",SUM(I14:K14)) | M14: =IF($B14="","",H14-L14) | N14: =IF($B14="","",IF(R14="Ancien",0,Paramètres!$D$21)) | P14: =IF($B14="","",N14-O14) | Q14: =IF($B14="","",IF(AND(M14<=0,P14<=0),"Soldé","En retard"))
H15: =IF($B15="","",Paramètres!$C$21) | L15: =IF($B15="","",SUM(I15:K15)) | M15: =IF($B15="","",H15-L15) | N15: =IF($B15="","",IF(R15="Ancien",0,Paramètres!$D$21)) | P15: =IF($B15="","",N15-O15) | Q15: =IF($B15="","",IF(AND(M15<=0,P15<=0),"Soldé","En retard"))
... H83: =IF($B83="","",Paramètres!$C$21) | L83: =IF($B83="","",SUM(I83:K83)) | M83: =IF($B83="","",H83-L83) | N83: =IF($B83="","",IF(R83="Ancien",0,Paramètres!$D$21)) | P83: =IF($B83="","",N83-O83) | Q83: =IF($B83="","",IF(AND(M83<=0,P83<=0),"Soldé","En retard"))

Sheet Classe CM2
A1: ="INSCRIPTIONS — "&Paramètres!$A$22 -> INSCRIPTIONS — CM2
A2: ="Année scolaire "&Paramètres!$C$11&" • Effectif : "&COUNTIF($B$4:$B$83,"?*")&" • Cellules jaunes = montants à saisir ; colonnes grises = calcul automatique" -> Année scolaire 2025-2026 • Effectif : 0 • Cellules jaunes = montants à saisir ; colonnes grises = calcul automatique
A3: Matricule | B3: Nom | C3: Prénom(s) | D3: Sexe | E3: Date de naissance | F3: Nom du tuteur | G3: Téléphone | H3: Scolarité due | I3: Tranche 1 | J3: Tranche 2 | K3: Tranche 3 | L3: Total payé | M3: Reste à payer | N3: Inscription due | O3: Inscription payée | P3: Reste inscription | Q3: Statut | R3: Nouveau / Ancien
H4: =IF($B4="","",Paramètres!$C$22) | L4: =IF($B4="","",SUM(I4:K4)) | M4: =IF($B4="","",H4-L4) | N4: =IF($B4="","",IF(R4="Ancien",0,Paramètres!$D$22)) | P4: =IF($B4="","",N4-O4) | Q4: =IF($B4="","",IF(AND(M4<=0,P4<=0),"Soldé","En retard"))
H5: =IF($B5="","",Paramètres!$C$22) | L5: =IF($B5="","",SUM(I5:K5)) | M5: =IF($B5="","",H5-L5) | N5: =IF($B5="","",IF(R5="Ancien",0,Paramètres!$D$22)) | P5: =IF($B5="","",N5-O5) | Q5: =IF($B5="","",IF(AND(M5<=0,P5<=0),"Soldé","En retard"))
H6: =IF($B6="","",Paramètres!$C$22) | L6: =IF($B6="","",SUM(I6:K6)) | M6: =IF($B6="","",H6-L6) | N6: =IF($B6="","",IF(R6="Ancien",0,Paramètres!$D$22)) | P6: =IF($B6="","",N6-O6) | Q6: =IF($B6="","",IF(AND(M6<=0,P6<=0),"Soldé","En retard"))
H7: =IF($B7="","",Paramètres!$C$22) | L7: =IF($B7="","",SUM(I7:K7)) | M7: =IF($B7="","",H7-L7) | N7: =IF($B7="","",IF(R7="Ancien",0,Paramètres!$D$22)) | P7: =IF($B7="","",N7-O7) | Q7: =IF($B7="","",IF(AND(M7<=0,P7<=0),"Soldé","En retard"))
H8: =IF($B8="","",Paramètres!$C$22) | L8: =IF($B8="","",SUM(I8:K8)) | M8: =IF($B8="","",H8-L8) | N8: =IF($B8="","",IF(R8="Ancien",0,Paramètres!$D$22)) | P8: =IF($B8="","",N8-O8) | Q8: =IF($B8="","",IF(AND(M8<=0,P8<=0),"Soldé","En retard"))
H9: =IF($B9="","",Paramètres!$C$22) | L9: =IF($B9="","",SUM(I9:K9)) | M9: =IF($B9="","",H9-L9) | N9: =IF($B9="","",IF(R9="Ancien",0,Paramètres!$D$22)) | P9: =IF($B9="","",N9-O9) | Q9: =IF($B9="","",IF(AND(M9<=0,P9<=0),"Soldé","En retard"))
H10: =IF($B10="","",Paramètres!$C$22) | L10: =IF($B10="","",SUM(I10:K10)) | M10: =IF($B10="","",H10-L10) | N10: =IF($B10="","",IF(R10="Ancien",0,Paramètres!$D$22)) | P10: =IF($B10="","",N10-O10) | Q10: =IF($B10="","",IF(AND(M10<=0,P10<=0),"Soldé","En retard"))
H11: =IF($B11="","",Paramètres!$C$22) | L11: =IF($B11="","",SUM(I11:K11)) | M11: =IF($B11="","",H11-L11) | N11: =IF($B11="","",IF(R11="Ancien",0,Paramètres!$D$22)) | P11: =IF($B11="","",N11-O11) | Q11: =IF($B11="","",IF(AND(M11<=0,P11<=0),"Soldé","En retard"))
H12: =IF($B12="","",Paramètres!$C$22) | L12: =IF($B12="","",SUM(I12:K12)) | M12: =IF($B12="","",H12-L12) | N12: =IF($B12="","",IF(R12="Ancien",0,Paramètres!$D$22)) | P12: =IF($B12="","",N12-O12) | Q12: =IF($B12="","",IF(AND(M12<=0,P12<=0),"Soldé","En retard"))
H13: =IF($B13="","",Paramètres!$C$22) | L13: =IF($B13="","",SUM(I13:K13)) | M13: =IF($B13="","",H13-L13) | N13: =IF($B13="","",IF(R13="Ancien",0,Paramètres!$D$22)) | P13: =IF($B13="","",N13-O13) | Q13: =IF($B13="","",IF(AND(M13<=0,P13<=0),"Soldé","En retard"))
H14: =IF($B14="","",Paramètres!$C$22) | L14: =IF($B14="","",SUM(I14:K14)) | M14: =IF($B14="","",H14-L14) | N14: =IF($B14="","",IF(R14="Ancien",0,Paramètres!$D$22)) | P14: =IF($B14="","",N14-O14) | Q14: =IF($B14="","",IF(AND(M14<=0,P14<=0),"Soldé","En retard"))
H15: =IF($B15="","",Paramètres!$C$22) | L15: =IF($B15="","",SUM(I15:K15)) | M15: =IF($B15="","",H15-L15) | N15: =IF($B15="","",IF(R15="Ancien",0,Paramètres!$D$22)) | P15: =IF($B15="","",N15-O15) | Q15: =IF($B15="","",IF(AND(M15<=0,P15<=0),"Soldé","En retard"))
... H83: =IF($B83="","",Paramètres!$C$22) | L83: =IF($B83="","",SUM(I83:K83)) | M83: =IF($B83="","",H83-L83) | N83: =IF($B83="","",IF(R83="Ancien",0,Paramètres!$D$22)) | P83: =IF($B83="","",N83-O83) | Q83: =IF($B83="","",IF(AND(M83<=0,P83<=0),"Soldé","En retard"))

Sheet Classe 6e
A1: ="INSCRIPTIONS — "&Paramètres!$A$23 -> INSCRIPTIONS — 6e
A2: ="Année scolaire "&Paramètres!$C$11&" • Effectif : "&COUNTIF($B$4:$B$83,"?*")&" • Cellules jaunes = montants à saisir ; colonnes grises = calcul automatique" -> Année scolaire 2025-2026 • Effectif : 0 • Cellules jaunes = montants à saisir ; colonnes grises = calcul automatique
A3: Matricule | B3: Nom | C3: Prénom(s) | D3: Sexe | E3: Date de naissance | F3: Nom du tuteur | G3: Téléphone | H3: Scolarité due | I3: Tranche 1 | J3: Tranche 2 | K3: Tranche 3 | L3: Total payé | M3: Reste à payer | N3: Inscription due | O3: Inscription payée | P3: Reste inscription | Q3: Statut | R3: Nouveau / Ancien
H4: =IF($B4="","",Paramètres!$C$23) | L4: =IF($B4="","",SUM(I4:K4)) | M4: =IF($B4="","",H4-L4) | N4: =IF($B4="","",IF(R4="Ancien",0,Paramètres!$D$23)) | P4: =IF($B4="","",N4-O4) | Q4: =IF($B4="","",IF(AND(M4<=0,P4<=0),"Soldé","En retard"))
H5: =IF($B5="","",Paramètres!$C$23) | L5: =IF($B5="","",SUM(I5:K5)) | M5: =IF($B5="","",H5-L5) | N5: =IF($B5="","",IF(R5="Ancien",0,Paramètres!$D$23)) | P5: =IF($B5="","",N5-O5) | Q5: =IF($B5="","",IF(AND(M5<=0,P5<=0),"Soldé","En retard"))
H6: =IF($B6="","",Paramètres!$C$23) | L6: =IF($B6="","",SUM(I6:K6)) | M6: =IF($B6="","",H6-L6) | N6: =IF($B6="","",IF(R6="Ancien",0,Paramètres!$D$23)) | P6: =IF($B6="","",N6-O6) | Q6: =IF($B6="","",IF(AND(M6<=0,P6<=0),"Soldé","En retard"))
H7: =IF($B7="","",Paramètres!$C$23) | L7: =IF($B7="","",SUM(I7:K7)) | M7: =IF($B7="","",H7-L7) | N7: =IF($B7="","",IF(R7="Ancien",0,Paramètres!$D$23)) | P7: =IF($B7="","",N7-O7) | Q7: =IF($B7="","",IF(AND(M7<=0,P7<=0),"Soldé","En retard"))
H8: =IF($B8="","",Paramètres!$C$23) | L8: =IF($B8="","",SUM(I8:K8)) | M8: =IF($B8="","",H8-L8) | N8: =IF($B8="","",IF(R8="Ancien",0,Paramètres!$D$23)) | P8: =IF($B8="","",N8-O8) | Q8: =IF($B8="","",IF(AND(M8<=0,P8<=0),"Soldé","En retard"))
H9: =IF($B9="","",Paramètres!$C$23) | L9: =IF($B9="","",SUM(I9:K9)) | M9: =IF($B9="","",H9-L9) | N9: =IF($B9="","",IF(R9="Ancien",0,Paramètres!$D$23)) | P9: =IF($B9="","",N9-O9) | Q9: =IF($B9="","",IF(AND(M9<=0,P9<=0),"Soldé","En retard"))
H10: =IF($B10="","",Paramètres!$C$23) | L10: =IF($B10="","",SUM(I10:K10)) | M10: =IF($B10="","",H10-L10) | N10: =IF($B10="","",IF(R10="Ancien",0,Paramètres!$D$23)) | P10: =IF($B10="","",N10-O10) | Q10: =IF($B10="","",IF(AND(M10<=0,P10<=0),"Soldé","En retard"))
H11: =IF($B11="","",Paramètres!$C$23) | L11: =IF($B11="","",SUM(I11:K11)) | M11: =IF($B11="","",H11-L11) | N11: =IF($B11="","",IF(R11="Ancien",0,Paramètres!$D$23)) | P11: =IF($B11="","",N11-O11) | Q11: =IF($B11="","",IF(AND(M11<=0,P11<=0),"Soldé","En retard"))
H12: =IF($B12="","",Paramètres!$C$23) | L12: =IF($B12="","",SUM(I12:K12)) | M12: =IF($B12="","",H12-L12) | N12: =IF($B12="","",IF(R12="Ancien",0,Paramètres!$D$23)) | P12: =IF($B12="","",N12-O12) | Q12: =IF($B12="","",IF(AND(M12<=0,P12<=0),"Soldé","En retard"))
H13: =IF($B13="","",Paramètres!$C$23) | L13: =IF($B13="","",SUM(I13:K13)) | M13: =IF($B13="","",H13-L13) | N13: =IF($B13="","",IF(R13="Ancien",0,Paramètres!$D$23)) | P13: =IF($B13="","",N13-O13) | Q13: =IF($B13="","",IF(AND(M13<=0,P13<=0),"Soldé","En retard"))
H14: =IF($B14="","",Paramètres!$C$23) | L14: =IF($B14="","",SUM(I14:K14)) | M14: =IF($B14="","",H14-L14) | N14: =IF($B14="","",IF(R14="Ancien",0,Paramètres!$D$23)) | P14: =IF($B14="","",N14-O14) | Q14: =IF($B14="","",IF(AND(M14<=0,P14<=0),"Soldé","En retard"))
H15: =IF($B15="","",Paramètres!$C$23) | L15: =IF($B15="","",SUM(I15:K15)) | M15: =IF($B15="","",H15-L15) | N15: =IF($B15="","",IF(R15="Ancien",0,Paramètres!$D$23)) | P15: =IF($B15="","",N15-O15) | Q15: =IF($B15="","",IF(AND(M15<=0,P15<=0),"Soldé","En retard"))
... H83: =IF($B83="","",Paramètres!$C$23) | L83: =IF($B83="","",SUM(I83:K83)) | M83: =IF($B83="","",H83-L83) | N83: =IF($B83="","",IF(R83="Ancien",0,Paramètres!$D$23)) | P83: =IF($B83="","",N83-O83) | Q83: =IF($B83="","",IF(AND(M83<=0,P83<=0),"Soldé","En retard"))

Sheet Classe 5e
A1: ="INSCRIPTIONS — "&Paramètres!$A$24 -> INSCRIPTIONS — 5e
A2: ="Année scolaire "&Paramètres!$C$11&" • Effectif : "&COUNTIF($B$4:$B$83,"?*")&" • Cellules jaunes = montants à saisir ; colonnes grises = calcul automatique" -> Année scolaire 2025-2026 • Effectif : 0 • Cellules jaunes = montants à saisir ; colonnes grises = calcul automatique
A3: Matricule | B3: Nom | C3: Prénom(s) | D3: Sexe | E3: Date de naissance | F3: Nom du tuteur | G3: Téléphone | H3: Scolarité due | I3: Tranche 1 | J3: Tranche 2 | K3: Tranche 3 | L3: Total payé | M3: Reste à payer | N3: Inscription due | O3: Inscription payée | P3: Reste inscription | Q3: Statut | R3: Nouveau / Ancien
H4: =IF($B4="","",Paramètres!$C$24) | L4: =IF($B4="","",SUM(I4:K4)) | M4: =IF($B4="","",H4-L4) | N4: =IF($B4="","",IF(R4="Ancien",0,Paramètres!$D$24)) | P4: =IF($B4="","",N4-O4) | Q4: =IF($B4="","",IF(AND(M4<=0,P4<=0),"Soldé","En retard"))
H5: =IF($B5="","",Paramètres!$C$24) | L5: =IF($B5="","",SUM(I5:K5)) | M5: =IF($B5="","",H5-L5) | N5: =IF($B5="","",IF(R5="Ancien",0,Paramètres!$D$24)) | P5: =IF($B5="","",N5-O5) | Q5: =IF($B5="","",IF(AND(M5<=0,P5<=0),"Soldé","En retard"))
H6: =IF($B6="","",Paramètres!$C$24) | L6: =IF($B6="","",SUM(I6:K6)) | M6: =IF($B6="","",H6-L6) | N6: =IF($B6="","",IF(R6="Ancien",0,Paramètres!$D$24)) | P6: =IF($B6="","",N6-O6) | Q6: =IF($B6="","",IF(AND(M6<=0,P6<=0),"Soldé","En retard"))
H7: =IF($B7="","",Paramètres!$C$24) | L7: =IF($B7="","",SUM(I7:K7)) | M7: =IF($B7="","",H7-L7) | N7: =IF($B7="","",IF(R7="Ancien",0,Paramètres!$D$24)) | P7: =IF($B7="","",N7-O7) | Q7: =IF($B7="","",IF(AND(M7<=0,P7<=0),"Soldé","En retard"))
H8: =IF($B8="","",Paramètres!$C$24) | L8: =IF($B8="","",SUM(I8:K8)) | M8: =IF($B8="","",H8-L8) | N8: =IF($B8="","",IF(R8="Ancien",0,Paramètres!$D$24)) | P8: =IF($B8="","",N8-O8) | Q8: =IF($B8="","",IF(AND(M8<=0,P8<=0),"Soldé","En retard"))
H9: =IF($B9="","",Paramètres!$C$24) | L9: =IF($B9="","",SUM(I9:K9)) | M9: =IF($B9="","",H9-L9) | N9: =IF($B9="","",IF(R9="Ancien",0,Paramètres!$D$24)) | P9: =IF($B9="","",N9-O9) | Q9: =IF($B9="","",IF(AND(M9<=0,P9<=0),"Soldé","En retard"))
H10: =IF($B10="","",Paramètres!$C$24) | L10: =IF($B10="","",SUM(I10:K10)) | M10: =IF($B10="","",H10-L10) | N10: =IF($B10="","",IF(R10="Ancien",0,Paramètres!$D$24)) | P10: =IF($B10="","",N10-O10) | Q10: =IF($B10="","",IF(AND(M10<=0,P10<=0),"Soldé","En retard"))
H11: =IF($B11="","",Paramètres!$C$24) | L11: =IF($B11="","",SUM(I11:K11)) | M11: =IF($B11="","",H11-L11) | N11: =IF($B11="","",IF(R11="Ancien",0,Paramètres!$D$24)) | P11: =IF($B11="","",N11-O11) | Q11: =IF($B11="","",IF(AND(M11<=0,P11<=0),"Soldé","En retard"))
H12: =IF($B12="","",Paramètres!$C$24) | L12: =IF($B12="","",SUM(I12:K12)) | M12: =IF($B12="","",H12-L12) | N12: =IF($B12="","",IF(R12="Ancien",0,Paramètres!$D$24)) | P12: =IF($B12="","",N12-O12) | Q12: =IF($B12="","",IF(AND(M12<=0,P12<=0),"Soldé","En retard"))
H13: =IF($B13="","",Paramètres!$C$24) | L13: =IF($B13="","",SUM(I13:K13)) | M13: =IF($B13="","",H13-L13) | N13: =IF($B13="","",IF(R13="Ancien",0,Paramètres!$D$24)) | P13: =IF($B13="","",N13-O13) | Q13: =IF($B13="","",IF(AND(M13<=0,P13<=0),"Soldé","En retard"))
H14: =IF($B14="","",Paramètres!$C$24) | L14: =IF($B14="","",SUM(I14:K14)) | M14: =IF($B14="","",H14-L14) | N14: =IF($B14="","",IF(R14="Ancien",0,Paramètres!$D$24)) | P14: =IF($B14="","",N14-O14) | Q14: =IF($B14="","",IF(AND(M14<=0,P14<=0),"Soldé","En retard"))
H15: =IF($B15="","",Paramètres!$C$24) | L15: =IF($B15="","",SUM(I15:K15)) | M15: =IF($B15="","",H15-L15) | N15: =IF($B15="","",IF(R15="Ancien",0,Paramètres!$D$24)) | P15: =IF($B15="","",N15-O15) | Q15: =IF($B15="","",IF(AND(M15<=0,P15<=0),"Soldé","En retard"))
... H83: =IF($B83="","",Paramètres!$C$24) | L83: =IF($B83="","",SUM(I83:K83)) | M83: =IF($B83="","",H83-L83) | N83: =IF($B83="","",IF(R83="Ancien",0,Paramètres!$D$24)) | P83: =IF($B83="","",N83-O83) | Q83: =IF($B83="","",IF(AND(M83<=0,P83<=0),"Soldé","En retard"))

Sheet Classe 4e
A1: ="INSCRIPTIONS — "&Paramètres!$A$25 -> INSCRIPTIONS — 4e
A2: ="Année scolaire "&Paramètres!$C$11&" • Effectif : "&COUNTIF($B$4:$B$83,"?*")&" • Cellules jaunes = montants à saisir ; colonnes grises = calcul automatique" -> Année scolaire 2025-2026 • Effectif : 1 • Cellules jaunes = montants à saisir ; colonnes grises = calcul automatique
A3: Matricule | B3: Nom | C3: Prénom(s) | D3: Sexe | E3: Date de naissance | F3: Nom du tuteur | G3: Téléphone | H3: Scolarité due | I3: Tranche 1 | J3: Tranche 2 | K3: Tranche 3 | L3: Total payé | M3: Reste à payer | N3: Inscription due | O3: Inscription payée | P3: Reste inscription | Q3: Statut | R3: Nouveau / Ancien
A4: 2025-001 | B4: DAOUDA | C4: Falmata | D4: F | E4: 2015-09-14 | F4: Daouda Marthé | G4: +227 90 00 00 00 | H4: =IF($B4="","",Paramètres!$C$25) -> 150000 | I4: 150000 | L4: =IF($B4="","",SUM(I4:K4)) -> 150000 | M4: =IF($B4="","",H4-L4) -> 0 | N4: =IF($B4="","",IF(R4="Ancien",0,Paramètres!$D$25)) -> 3000 | P4: =IF($B4="","",N4-O4) -> 3000 | Q4: =IF($B4="","",IF(AND(M4<=0,P4<=0),"Soldé","En retard")) -> En retard
H5: =IF($B5="","",Paramètres!$C$25) | L5: =IF($B5="","",SUM(I5:K5)) | M5: =IF($B5="","",H5-L5) | N5: =IF($B5="","",IF(R5="Ancien",0,Paramètres!$D$25)) | P5: =IF($B5="","",N5-O5) | Q5: =IF($B5="","",IF(AND(M5<=0,P5<=0),"Soldé","En retard"))
H6: =IF($B6="","",Paramètres!$C$25) | L6: =IF($B6="","",SUM(I6:K6)) | M6: =IF($B6="","",H6-L6) | N6: =IF($B6="","",IF(R6="Ancien",0,Paramètres!$D$25)) | P6: =IF($B6="","",N6-O6) | Q6: =IF($B6="","",IF(AND(M6<=0,P6<=0),"Soldé","En retard"))
H7: =IF($B7="","",Paramètres!$C$25) | L7: =IF($B7="","",SUM(I7:K7)) | M7: =IF($B7="","",H7-L7) | N7: =IF($B7="","",IF(R7="Ancien",0,Paramètres!$D$25)) | P7: =IF($B7="","",N7-O7) | Q7: =IF($B7="","",IF(AND(M7<=0,P7<=0),"Soldé","En retard"))
H8: =IF($B8="","",Paramètres!$C$25) | L8: =IF($B8="","",SUM(I8:K8)) | M8: =IF($B8="","",H8-L8) | N8: =IF($B8="","",IF(R8="Ancien",0,Paramètres!$D$25)) | P8: =IF($B8="","",N8-O8) | Q8: =IF($B8="","",IF(AND(M8<=0,P8<=0),"Soldé","En retard"))
H9: =IF($B9="","",Paramètres!$C$25) | L9: =IF($B9="","",SUM(I9:K9)) | M9: =IF($B9="","",H9-L9) | N9: =IF($B9="","",IF(R9="Ancien",0,Paramètres!$D$25)) | P9: =IF($B9="","",N9-O9) | Q9: =IF($B9="","",IF(AND(M9<=0,P9<=0),"Soldé","En retard"))
H10: =IF($B10="","",Paramètres!$C$25) | L10: =IF($B10="","",SUM(I10:K10)) | M10: =IF($B10="","",H10-L10) | N10: =IF($B10="","",IF(R10="Ancien",0,Paramètres!$D$25)) | P10: =IF($B10="","",N10-O10) | Q10: =IF($B10="","",IF(AND(M10<=0,P10<=0),"Soldé","En retard"))
H11: =IF($B11="","",Paramètres!$C$25) | L11: =IF($B11="","",SUM(I11:K11)) | M11: =IF($B11="","",H11-L11) | N11: =IF($B11="","",IF(R11="Ancien",0,Paramètres!$D$25)) | P11: =IF($B11="","",N11-O11) | Q11: =IF($B11="","",IF(AND(M11<=0,P11<=0),"Soldé","En retard"))
H12: =IF($B12="","",Paramètres!$C$25) | L12: =IF($B12="","",SUM(I12:K12)) | M12: =IF($B12="","",H12-L12) | N12: =IF($B12="","",IF(R12="Ancien",0,Paramètres!$D$25)) | P12: =IF($B12="","",N12-O12) | Q12: =IF($B12="","",IF(AND(M12<=0,P12<=0),"Soldé","En retard"))
H13: =IF($B13="","",Paramètres!$C$25) | L13: =IF($B13="","",SUM(I13:K13)) | M13: =IF($B13="","",H13-L13) | N13: =IF($B13="","",IF(R13="Ancien",0,Paramètres!$D$25)) | P13: =IF($B13="","",N13-O13) | Q13: =IF($B13="","",IF(AND(M13<=0,P13<=0),"Soldé","En retard"))
H14: =IF($B14="","",Paramètres!$C$25) | L14: =IF($B14="","",SUM(I14:K14)) | M14: =IF($B14="","",H14-L14) | N14: =IF($B14="","",IF(R14="Ancien",0,Paramètres!$D$25)) | P14: =IF($B14="","",N14-O14) | Q14: =IF($B14="","",IF(AND(M14<=0,P14<=0),"Soldé","En retard"))
H15: =IF($B15="","",Paramètres!$C$25) | L15: =IF($B15="","",SUM(I15:K15)) | M15: =IF($B15="","",H15-L15) | N15: =IF($B15="","",IF(R15="Ancien",0,Paramètres!$D$25)) | P15: =IF($B15="","",N15-O15) | Q15: =IF($B15="","",IF(AND(M15<=0,P15<=0),"Soldé","En retard"))
H16: =IF($B16="","",Paramètres!$C$25) | L16: =IF($B16="","",SUM(I16:K16)) | M16: =IF($B16="","",H16-L16) | N16: =IF($B16="","",IF(R16="Ancien",0,Paramètres!$D$25)) | P16: =IF($B16="","",N16-O16) | Q16: =IF($B16="","",IF(AND(M16<=0,P16<=0),"Soldé","En retard"))
... H83: =IF($B83="","",Paramètres!$C$25) | L83: =IF($B83="","",SUM(I83:K83)) | M83: =IF($B83="","",H83-L83) | N83: =IF($B83="","",IF(R83="Ancien",0,Paramètres!$D$25)) | P83: =IF($B83="","",N83-O83) | Q83: =IF($B83="","",IF(AND(M83<=0,P83<=0),"Soldé","En retard"))

Sheet Classe 3e
A1: ="INSCRIPTIONS — "&Paramètres!$A$26 -> INSCRIPTIONS — 3e
A2: ="Année scolaire "&Paramètres!$C$11&" • Effectif : "&COUNTIF($B$4:$B$83,"?*")&" • Cellules jaunes = montants à saisir ; colonnes grises = calcul automatique" -> Année scolaire 2025-2026 • Effectif : 0 • Cellules jaunes = montants à saisir ; colonnes grises = calcul automatique
A3: Matricule | B3: Nom | C3: Prénom(s) | D3: Sexe | E3: Date de naissance | F3: Nom du tuteur | G3: Téléphone | H3: Scolarité due | I3: Tranche 1 | J3: Tranche 2 | K3: Tranche 3 | L3: Total payé | M3: Reste à payer | N3: Inscription due | O3: Inscription payée | P3: Reste inscription | Q3: Statut | R3: Nouveau / Ancien
H4: =IF($B4="","",Paramètres!$C$26) | L4: =IF($B4="","",SUM(I4:K4)) | M4: =IF($B4="","",H4-L4) | N4: =IF($B4="","",IF(R4="Ancien",0,Paramètres!$D$26)) | P4: =IF($B4="","",N4-O4) | Q4: =IF($B4="","",IF(AND(M4<=0,P4<=0),"Soldé","En retard"))
H5: =IF($B5="","",Paramètres!$C$26) | L5: =IF($B5="","",SUM(I5:K5)) | M5: =IF($B5="","",H5-L5) | N5: =IF($B5="","",IF(R5="Ancien",0,Paramètres!$D$26)) | P5: =IF($B5="","",N5-O5) | Q5: =IF($B5="","",IF(AND(M5<=0,P5<=0),"Soldé","En retard"))
H6: =IF($B6="","",Paramètres!$C$26) | L6: =IF($B6="","",SUM(I6:K6)) | M6: =IF($B6="","",H6-L6) | N6: =IF($B6="","",IF(R6="Ancien",0,Paramètres!$D$26)) | P6: =IF($B6="","",N6-O6) | Q6: =IF($B6="","",IF(AND(M6<=0,P6<=0),"Soldé","En retard"))
H7: =IF($B7="","",Paramètres!$C$26) | L7: =IF($B7="","",SUM(I7:K7)) | M7: =IF($B7="","",H7-L7) | N7: =IF($B7="","",IF(R7="Ancien",0,Paramètres!$D$26)) | P7: =IF($B7="","",N7-O7) | Q7: =IF($B7="","",IF(AND(M7<=0,P7<=0),"Soldé","En retard"))
H8: =IF($B8="","",Paramètres!$C$26) | L8: =IF($B8="","",SUM(I8:K8)) | M8: =IF($B8="","",H8-L8) | N8: =IF($B8="","",IF(R8="Ancien",0,Paramètres!$D$26)) | P8: =IF($B8="","",N8-O8) | Q8: =IF($B8="","",IF(AND(M8<=0,P8<=0),"Soldé","En retard"))
H9: =IF($B9="","",Paramètres!$C$26) | L9: =IF($B9="","",SUM(I9:K9)) | M9: =IF($B9="","",H9-L9) | N9: =IF($B9="","",IF(R9="Ancien",0,Paramètres!$D$26)) | P9: =IF($B9="","",N9-O9) | Q9: =IF($B9="","",IF(AND(M9<=0,P9<=0),"Soldé","En retard"))
H10: =IF($B10="","",Paramètres!$C$26) | L10: =IF($B10="","",SUM(I10:K10)) | M10: =IF($B10="","",H10-L10) | N10: =IF($B10="","",IF(R10="Ancien",0,Paramètres!$D$26)) | P10: =IF($B10="","",N10-O10) | Q10: =IF($B10="","",IF(AND(M10<=0,P10<=0),"Soldé","En retard"))
H11: =IF($B11="","",Paramètres!$C$26) | L11: =IF($B11="","",SUM(I11:K11)) | M11: =IF($B11="","",H11-L11) | N11: =IF($B11="","",IF(R11="Ancien",0,Paramètres!$D$26)) | P11: =IF($B11="","",N11-O11) | Q11: =IF($B11="","",IF(AND(M11<=0,P11<=0),"Soldé","En retard"))
H12: =IF($B12="","",Paramètres!$C$26) | L12: =IF($B12="","",SUM(I12:K12)) | M12: =IF($B12="","",H12-L12) | N12: =IF($B12="","",IF(R12="Ancien",0,Paramètres!$D$26)) | P12: =IF($B12="","",N12-O12) | Q12: =IF($B12="","",IF(AND(M12<=0,P12<=0),"Soldé","En retard"))
H13: =IF($B13="","",Paramètres!$C$26) | L13: =IF($B13="","",SUM(I13:K13)) | M13: =IF($B13="","",H13-L13) | N13: =IF($B13="","",IF(R13="Ancien",0,Paramètres!$D$26)) | P13: =IF($B13="","",N13-O13) | Q13: =IF($B13="","",IF(AND(M13<=0,P13<=0),"Soldé","En retard"))
H14: =IF($B14="","",Paramètres!$C$26) | L14: =IF($B14="","",SUM(I14:K14)) | M14: =IF($B14="","",H14-L14) | N14: =IF($B14="","",IF(R14="Ancien",0,Paramètres!$D$26)) | P14: =IF($B14="","",N14-O14) | Q14: =IF($B14="","",IF(AND(M14<=0,P14<=0),"Soldé","En retard"))
H15: =IF($B15="","",Paramètres!$C$26) | L15: =IF($B15="","",SUM(I15:K15)) | M15: =IF($B15="","",H15-L15) | N15: =IF($B15="","",IF(R15="Ancien",0,Paramètres!$D$26)) | P15: =IF($B15="","",N15-O15) | Q15: =IF($B15="","",IF(AND(M15<=0,P15<=0),"Soldé","En retard"))
... H83: =IF($B83="","",Paramètres!$C$26) | L83: =IF($B83="","",SUM(I83:K83)) | M83: =IF($B83="","",H83-L83) | N83: =IF($B83="","",IF(R83="Ancien",0,Paramètres!$D$26)) | P83: =IF($B83="","",N83-O83) | Q83: =IF($B83="","",IF(AND(M83<=0,P83<=0),"Soldé","En retard"))

Sheet Classe 2nde
A1: ="INSCRIPTIONS — "&Paramètres!$A$27 -> INSCRIPTIONS — 2nde
A2: ="Année scolaire "&Paramètres!$C$11&" • Effectif : "&COUNTIF($B$4:$B$83,"?*")&" • Cellules jaunes = montants à saisir ; colonnes grises = calcul automatique" -> Année scolaire 2025-2026 • Effectif : 1 • Cellules jaunes = montants à saisir ; colonnes grises = calcul automatique
A3: Matricule | B3: Nom | C3: Prénom(s) | D3: Sexe | E3: Date de naissance | F3: Nom du tuteur | G3: Téléphone | H3: Scolarité due | I3: Tranche 1 | J3: Tranche 2 | K3: Tranche 3 | L3: Total payé | M3: Reste à payer | N3: Inscription due | O3: Inscription payée | P3: Reste inscription | Q3: Statut | R3: Nouveau / Ancien
A4: 2025-002 | B4: DAOUDA | C4: Arimi | D4: M | E4: 36804 | F4: Daouda Marthé | G4: +227 90 00 00 00 | H4: =IF($B4="","",Paramètres!$C$27) -> 150000 | I4: 50000 | L4: =IF($B4="","",SUM(I4:K4)) -> 50000 | M4: =IF($B4="","",H4-L4) -> 100000 | N4: =IF($B4="","",IF(R4="Ancien",0,Paramètres!$D$27)) -> 3000 | P4: =IF($B4="","",N4-O4) -> 3000 | Q4: =IF($B4="","",IF(AND(M4<=0,P4<=0),"Soldé","En retard")) -> En retard
H5: =IF($B5="","",Paramètres!$C$27) | L5: =IF($B5="","",SUM(I5:K5)) | M5: =IF($B5="","",H5-L5) | N5: =IF($B5="","",IF(R5="Ancien",0,Paramètres!$D$27)) | P5: =IF($B5="","",N5-O5) | Q5: =IF($B5="","",IF(AND(M5<=0,P5<=0),"Soldé","En retard"))
H6: =IF($B6="","",Paramètres!$C$27) | L6: =IF($B6="","",SUM(I6:K6)) | M6: =IF($B6="","",H6-L6) | N6: =IF($B6="","",IF(R6="Ancien",0,Paramètres!$D$27)) | P6: =IF($B6="","",N6-O6) | Q6: =IF($B6="","",IF(AND(M6<=0,P6<=0),"Soldé","En retard"))
H7: =IF($B7="","",Paramètres!$C$27) | L7: =IF($B7="","",SUM(I7:K7)) | M7: =IF($B7="","",H7-L7) | N7: =IF($B7="","",IF(R7="Ancien",0,Paramètres!$D$27)) | P7: =IF($B7="","",N7-O7) | Q7: =IF($B7="","",IF(AND(M7<=0,P7<=0),"Soldé","En retard"))
H8: =IF($B8="","",Paramètres!$C$27) | L8: =IF($B8="","",SUM(I8:K8)) | M8: =IF($B8="","",H8-L8) | N8: =IF($B8="","",IF(R8="Ancien",0,Paramètres!$D$27)) | P8: =IF($B8="","",N8-O8) | Q8: =IF($B8="","",IF(AND(M8<=0,P8<=0),"Soldé","En retard"))
H9: =IF($B9="","",Paramètres!$C$27) | L9: =IF($B9="","",SUM(I9:K9)) | M9: =IF($B9="","",H9-L9) | N9: =IF($B9="","",IF(R9="Ancien",0,Paramètres!$D$27)) | P9: =IF($B9="","",N9-O9) | Q9: =IF($B9="","",IF(AND(M9<=0,P9<=0),"Soldé","En retard"))
H10: =IF($B10="","",Paramètres!$C$27) | L10: =IF($B10="","",SUM(I10:K10)) | M10: =IF($B10="","",H10-L10) | N10: =IF($B10="","",IF(R10="Ancien",0,Paramètres!$D$27)) | P10: =IF($B10="","",N10-O10) | Q10: =IF($B10="","",IF(AND(M10<=0,P10<=0),"Soldé","En retard"))
H11: =IF($B11="","",Paramètres!$C$27) | L11: =IF($B11="","",SUM(I11:K11)) | M11: =IF($B11="","",H11-L11) | N11: =IF($B11="","",IF(R11="Ancien",0,Paramètres!$D$27)) | P11: =IF($B11="","",N11-O11) | Q11: =IF($B11="","",IF(AND(M11<=0,P11<=0),"Soldé","En retard"))
H12: =IF($B12="","",Paramètres!$C$27) | L12: =IF($B12="","",SUM(I12:K12)) | M12: =IF($B12="","",H12-L12) | N12: =IF($B12="","",IF(R12="Ancien",0,Paramètres!$D$27)) | P12: =IF($B12="","",N12-O12) | Q12: =IF($B12="","",IF(AND(M12<=0,P12<=0),"Soldé","En retard"))
H13: =IF($B13="","",Paramètres!$C$27) | L13: =IF($B13="","",SUM(I13:K13)) | M13: =IF($B13="","",H13-L13) | N13: =IF($B13="","",IF(R13="Ancien",0,Paramètres!$D$27)) | P13: =IF($B13="","",N13-O13) | Q13: =IF($B13="","",IF(AND(M13<=0,P13<=0),"Soldé","En retard"))
H14: =IF($B14="","",Paramètres!$C$27) | L14: =IF($B14="","",SUM(I14:K14)) | M14: =IF($B14="","",H14-L14) | N14: =IF($B14="","",IF(R14="Ancien",0,Paramètres!$D$27)) | P14: =IF($B14="","",N14-O14) | Q14: =IF($B14="","",IF(AND(M14<=0,P14<=0),"Soldé","En retard"))
H15: =IF($B15="","",Paramètres!$C$27) | L15: =IF($B15="","",SUM(I15:K15)) | M15: =IF($B15="","",H15-L15) | N15: =IF($B15="","",IF(R15="Ancien",0,Paramètres!$D$27)) | P15: =IF($B15="","",N15-O15) | Q15: =IF($B15="","",IF(AND(M15<=0,P15<=0),"Soldé","En retard"))
H16: =IF($B16="","",Paramètres!$C$27) | L16: =IF($B16="","",SUM(I16:K16)) | M16: =IF($B16="","",H16-L16) | N16: =IF($B16="","",IF(R16="Ancien",0,Paramètres!$D$27)) | P16: =IF($B16="","",N16-O16) | Q16: =IF($B16="","",IF(AND(M16<=0,P16<=0),"Soldé","En retard"))
... H83: =IF($B83="","",Paramètres!$C$27) | L83: =IF($B83="","",SUM(I83:K83)) | M83: =IF($B83="","",H83-L83) | N83: =IF($B83="","",IF(R83="Ancien",0,Paramètres!$D$27)) | P83: =IF($B83="","",N83-O83) | Q83: =IF($B83="","",IF(AND(M83<=0,P83<=0),"Soldé","En retard"))

Sheet Classe 1ère A
A1: ="INSCRIPTIONS — "&Paramètres!$A$28 -> INSCRIPTIONS — 1ère A
A2: ="Année scolaire "&Paramètres!$C$11&" • Effectif : "&COUNTIF($B$4:$B$83,"?*")&" • Cellules jaunes = montants à saisir ; colonnes grises = calcul automatique" -> Année scolaire 2025-2026 • Effectif : 0 • Cellules jaunes = montants à saisir ; colonnes grises = calcul automatique
A3: Matricule | B3: Nom | C3: Prénom(s) | D3: Sexe | E3: Date de naissance | F3: Nom du tuteur | G3: Téléphone | H3: Scolarité due | I3: Tranche 1 | J3: Tranche 2 | K3: Tranche 3 | L3: Total payé | M3: Reste à payer | N3: Inscription due | O3: Inscription payée | P3: Reste inscription | Q3: Statut | R3: Nouveau / Ancien
H4: =IF($B4="","",Paramètres!$C$28) | L4: =IF($B4="","",SUM(I4:K4)) | M4: =IF($B4="","",H4-L4) | N4: =IF($B4="","",IF(R4="Ancien",0,Paramètres!$D$28)) | P4: =IF($B4="","",N4-O4) | Q4: =IF($B4="","",IF(AND(M4<=0,P4<=0),"Soldé","En retard"))
H5: =IF($B5="","",Paramètres!$C$28) | L5: =IF($B5="","",SUM(I5:K5)) | M5: =IF($B5="","",H5-L5) | N5: =IF($B5="","",IF(R5="Ancien",0,Paramètres!$D$28)) | P5: =IF($B5="","",N5-O5) | Q5: =IF($B5="","",IF(AND(M5<=0,P5<=0),"Soldé","En retard"))
H6: =IF($B6="","",Paramètres!$C$28) | L6: =IF($B6="","",SUM(I6:K6)) | M6: =IF($B6="","",H6-L6) | N6: =IF($B6="","",IF(R6="Ancien",0,Paramètres!$D$28)) | P6: =IF($B6="","",N6-O6) | Q6: =IF($B6="","",IF(AND(M6<=0,P6<=0),"Soldé","En retard"))
H7: =IF($B7="","",Paramètres!$C$28) | L7: =IF($B7="","",SUM(I7:K7)) | M7: =IF($B7="","",H7-L7) | N7: =IF($B7="","",IF(R7="Ancien",0,Paramètres!$D$28)) | P7: =IF($B7="","",N7-O7) | Q7: =IF($B7="","",IF(AND(M7<=0,P7<=0),"Soldé","En retard"))
H8: =IF($B8="","",Paramètres!$C$28) | L8: =IF($B8="","",SUM(I8:K8)) | M8: =IF($B8="","",H8-L8) | N8: =IF($B8="","",IF(R8="Ancien",0,Paramètres!$D$28)) | P8: =IF($B8="","",N8-O8) | Q8: =IF($B8="","",IF(AND(M8<=0,P8<=0),"Soldé","En retard"))
H9: =IF($B9="","",Paramètres!$C$28) | L9: =IF($B9="","",SUM(I9:K9)) | M9: =IF($B9="","",H9-L9) | N9: =IF($B9="","",IF(R9="Ancien",0,Paramètres!$D$28)) | P9: =IF($B9="","",N9-O9) | Q9: =IF($B9="","",IF(AND(M9<=0,P9<=0),"Soldé","En retard"))
H10: =IF($B10="","",Paramètres!$C$28) | L10: =IF($B10="","",SUM(I10:K10)) | M10: =IF($B10="","",H10-L10) | N10: =IF($B10="","",IF(R10="Ancien",0,Paramètres!$D$28)) | P10: =IF($B10="","",N10-O10) | Q10: =IF($B10="","",IF(AND(M10<=0,P10<=0),"Soldé","En retard"))
H11: =IF($B11="","",Paramètres!$C$28) | L11: =IF($B11="","",SUM(I11:K11)) | M11: =IF($B11="","",H11-L11) | N11: =IF($B11="","",IF(R11="Ancien",0,Paramètres!$D$28)) | P11: =IF($B11="","",N11-O11) | Q11: =IF($B11="","",IF(AND(M11<=0,P11<=0),"Soldé","En retard"))
H12: =IF($B12="","",Paramètres!$C$28) | L12: =IF($B12="","",SUM(I12:K12)) | M12: =IF($B12="","",H12-L12) | N12: =IF($B12="","",IF(R12="Ancien",0,Paramètres!$D$28)) | P12: =IF($B12="","",N12-O12) | Q12: =IF($B12="","",IF(AND(M12<=0,P12<=0),"Soldé","En retard"))
H13: =IF($B13="","",Paramètres!$C$28) | L13: =IF($B13="","",SUM(I13:K13)) | M13: =IF($B13="","",H13-L13) | N13: =IF($B13="","",IF(R13="Ancien",0,Paramètres!$D$28)) | P13: =IF($B13="","",N13-O13) | Q13: =IF($B13="","",IF(AND(M13<=0,P13<=0),"Soldé","En retard"))
H14: =IF($B14="","",Paramètres!$C$28) | L14: =IF($B14="","",SUM(I14:K14)) | M14: =IF($B14="","",H14-L14) | N14: =IF($B14="","",IF(R14="Ancien",0,Paramètres!$D$28)) | P14: =IF($B14="","",N14-O14) | Q14: =IF($B14="","",IF(AND(M14<=0,P14<=0),"Soldé","En retard"))
H15: =IF($B15="","",Paramètres!$C$28) | L15: =IF($B15="","",SUM(I15:K15)) | M15: =IF($B15="","",H15-L15) | N15: =IF($B15="","",IF(R15="Ancien",0,Paramètres!$D$28)) | P15: =IF($B15="","",N15-O15) | Q15: =IF($B15="","",IF(AND(M15<=0,P15<=0),"Soldé","En retard"))
... H83: =IF($B83="","",Paramètres!$C$28) | L83: =IF($B83="","",SUM(I83:K83)) | M83: =IF($B83="","",H83-L83) | N83: =IF($B83="","",IF(R83="Ancien",0,Paramètres!$D$28)) | P83: =IF($B83="","",N83-O83) | Q83: =IF($B83="","",IF(AND(M83<=0,P83<=0),"Soldé","En retard"))

Sheet Classe 1ère D
A1: ="INSCRIPTIONS — "&Paramètres!$A$29 -> INSCRIPTIONS — 1ère D
A2: ="Année scolaire "&Paramètres!$C$11&" • Effectif : "&COUNTIF($B$4:$B$83,"?*")&" • Cellules jaunes = montants à saisir ; colonnes grises = calcul automatique" -> Année scolaire 2025-2026 • Effectif : 0 • Cellules jaunes = montants à saisir ; colonnes grises = calcul automatique
A3: Matricule | B3: Nom | C3: Prénom(s) | D3: Sexe | E3: Date de naissance | F3: Nom du tuteur | G3: Téléphone | H3: Scolarité due | I3: Tranche 1 | J3: Tranche 2 | K3: Tranche 3 | L3: Total payé | M3: Reste à payer | N3: Inscription due | O3: Inscription payée | P3: Reste inscription | Q3: Statut | R3: Nouveau / Ancien
H4: =IF($B4="","",Paramètres!$C$29) | L4: =IF($B4="","",SUM(I4:K4)) | M4: =IF($B4="","",H4-L4) | N4: =IF($B4="","",IF(R4="Ancien",0,Paramètres!$D$29)) | P4: =IF($B4="","",N4-O4) | Q4: =IF($B4="","",IF(AND(M4<=0,P4<=0),"Soldé","En retard"))
H5: =IF($B5="","",Paramètres!$C$29) | L5: =IF($B5="","",SUM(I5:K5)) | M5: =IF($B5="","",H5-L5) | N5: =IF($B5="","",IF(R5="Ancien",0,Paramètres!$D$29)) | P5: =IF($B5="","",N5-O5) | Q5: =IF($B5="","",IF(AND(M5<=0,P5<=0),"Soldé","En retard"))
H6: =IF($B6="","",Paramètres!$C$29) | L6: =IF($B6="","",SUM(I6:K6)) | M6: =IF($B6="","",H6-L6) | N6: =IF($B6="","",IF(R6="Ancien",0,Paramètres!$D$29)) | P6: =IF($B6="","",N6-O6) | Q6: =IF($B6="","",IF(AND(M6<=0,P6<=0),"Soldé","En retard"))
H7: =IF($B7="","",Paramètres!$C$29) | L7: =IF($B7="","",SUM(I7:K7)) | M7: =IF($B7="","",H7-L7) | N7: =IF($B7="","",IF(R7="Ancien",0,Paramètres!$D$29)) | P7: =IF($B7="","",N7-O7) | Q7: =IF($B7="","",IF(AND(M7<=0,P7<=0),"Soldé","En retard"))
H8: =IF($B8="","",Paramètres!$C$29) | L8: =IF($B8="","",SUM(I8:K8)) | M8: =IF($B8="","",H8-L8) | N8: =IF($B8="","",IF(R8="Ancien",0,Paramètres!$D$29)) | P8: =IF($B8="","",N8-O8) | Q8: =IF($B8="","",IF(AND(M8<=0,P8<=0),"Soldé","En retard"))
